Workbook

Sheet 115自留(季)
C1: 險種代號 | D1: 0100 | E1: 0200 | F1: 0300 | G1: 0400 | H1: 0500 | I1: 0600 | J1: 0700 | K1: 0800 | L1: 0900 | M1: 1000 | N1: 1100 | O1: 1200 | P1: 1300 | Q1: 1400 | R1: 1500 | S1: 1600 | T1: 1700 | U1: 1800 | V1: 1900 | W1: 2000 | X1: 2100 | Y1: 2200 | Z1: 2300 | AA1: 2400 | AB1: 2500 | AC1: 2600 | AD1: 2700 | AE1: 2800 | AF1: 2900 | AJ1: 9900
A2: 代號 | B2: 月份 | C2: 公司別/險種 | D2: 一年期住宅火險 | E2: 長期住宅火險 | F2: 一年期商業火險 | G2: 長期商業火險 | H2: 內陸運輸險 | I2: 貨物運輸險 | J2: 船體險 | K2: 漁船險 | L2: 航空險 | M2: 自用車損險 | N2: 商業車損險 | O2: 自用車責險 | P2: 商業車責險 | Q2: 強制自用車責險 | R2: 強制商業車責險 | S2: 強制機車責險 | T2: 一般責任險 | U2: 專業責任險 | V2: 工程險 | W2: 核能險 | X2: 保證險 | Y2: 信用險 | Z2: 其他財產保險 | AA2: 傷害險 | AB2: 商業地震險 | AC2: 個人綜險 | AD2: 商業綜險 | AE2: 颱風洪水險 | AF2: 政策地震險 | AG2: 一年期 健康險 | AH2: 長年期 健康險 | AI2: 強制電動二輪 | AJ2: 國外分進 | AK2: 合計
A3: 01 | B3: 1-1Q(1-3) | C3: 台產 | D3: 86311063 | E3: -19246 | F3: 2625383 | G3: -1471 | H3: 485945 | I3: 21439304 | J3: 16000449 | K3: 629521 | L3: 820658 | M3: 268696228 | N3: 8397217 | O3: 564422776 | P3: 107339443 | Q3: 93008050 | R3: 15189994 | S3: 55237289 | T3: 61087257 | U3: 2411440 | V3: 46911029 | W3: 447586 | X3: 2334390 | Y3: 0 | Z3: 6224521 | AA3: 158015657 | AB3: 19139376 | AC3: 51294098 | AD3: 9741033 | AE3: 20115492 | AF3: 20759064 | AG3: 36516642 | AH3: 0 | AI3: 1006055 | AJ3: 57202 | AK3: =SUM(D3:AJ3) -> 1676643445
A4: 02 | B4: 1-1Q(1-3) | C4: 兆豐 | D4: 70525269 | E4: -4068 | F4: 60947725 | G4: 0 | H4: -420735 | I4: 30271693 | J4: 15406837 | K4: 2805160 | L4: 12509798 | M4: 4.0956687e+08 | N4: 13667347 | O4: 3.2272711e+08 | P4: 44999415 | Q4: 58366243 | R4: 7095319 | S4: 21690368 | T4: 1.1262447e+08 | U4: 13546634 | V4: 120183253 | W4: 4112105 | X4: 3477547.8 | Y4: -537872 | Z4: 32935473 | AA4: 98670081 | AB4: 68186041 | AC4: 10245179 | AD4: 0 | AE4: 51006049 | AF4: 18192839 | AG4: 23749680 | AH4: 54687 | AI4: 392313 | AJ4: 43495460 | AK4: =SUM(D4:AJ4) -> 1670488295
A5: 05 | B5: 1-1Q(1-3) | C5: 富邦 | D5: 70317321 | E5: -5285 | F5: 2.5596473e+08 | G5: 0 | H5: 1.0091392e+08 | I5: 2.0589424e+08 | J5: 8885317.7 | K5: 8352721.1 | L5: 2729734.7 | M5: 1825362600 | N5: 70210998 | O5: 2994775865 | P5: 656517992 | Q5: 458272220 | R5: 81342179 | S5: 642426561 | T5: 1.073086e+09 | U5: 1.1452936e+08 | V5: 2.2747526e+08 | W5: 4327491 | X5: 16022156 | Y5: 1019788.6 | Z5: 2.4488394e+08 | AA5: 2054719954 | AB5: 1.1519951e+08 | AC5: 472061336 | AD5: 8051058 | AE5: 1.0197428e+08 | AF5: 22355529 | AG5: 827747829 | AH5: 0 | AI5: 32675497 | AJ5: 89714652 | AK5: =SUM(D5:AJ5) -> 12787804788
A6: 06 | B6: 1-1Q(1-3) | C6: 和泰 | D6: 11585999 | E6: -13203 | F6: 110340806 | G6: 0 | H6: 18764186 | I6: 37792634 | J6: 14592 | K6: 24160 | L6: 26 | M6: 1382746355 | N6: 6699297 | O6: 778589965 | P6: 36340217 | Q6: 111188006 | R6: 13517129 | S6: 18370804 | T6: 126063151 | U6: 11779813 | V6: 112365322 | W6: 87987 | X6: 1699408 | Y6: 0 | Z6: 2644271 | AA6: 181051884 | AB6: 55248261 | AC6: 3944661 | AD6: 1993501 | AE6: 51697356 | AF6: 5008479 | AG6: 42425346 | AI6: 375219 | AJ6: 2173666 | AK6: =SUM(D6:AJ6) -> 3124519298
A7: 07 | B7: 1-1Q(1-3) | C7: 泰安 | D7: 16623117 | E7: 76 | F7: 174299728 | G7: 0 | H7: 20451686 | I7: 25232927 | J7: 3162183 | K7: 6439831 | L7: 0 | M7: 605951046 | N7: 10849889 | O7: 660868051 | P7: 52769665 | Q7: 127393946 | R7: 12870377 | S7: 64447852 | T7: 184406422 | U7: 4393595 | V7: 121634108 | W7: 655117 | X7: 1281043 | Y7: 0 | Z7: 3139090 | AA7: 209063283 | AB7: 26304297 | AC7: 56128997 | AD7: 362429 | AE7: 24223478 | AF7: 9720208 | AG7: 22025709 | AH7: 0 | AI7: 2429172 | AJ7: 0 | AK7: =SUM(D7:AJ7) -> 2447127322
A8: 08 | B8: 1-1Q(1-3) | C8: 明台 | D8: 42120340 | E8: 746 | F8: 127787712 | G8: 0 | H8: 21027770 | I8: 47332373 | J8: 159986 | K8: 26506030 | L8: -29507 | M8: 781592636 | N8: 33393441 | O8: 773191743 | P8: 119709612 | Q8: 155771054 | R8: 20947598 | S8: 62881172 | T8: 241814168 | U8: 29021596 | V8: 84204258 | W8: 701661 | X8: 4146930 | Y8: -4017356 | Z8: 53111329 | AA8: 161237056 | AB8: 21682396 | AC8: 37117064 | AD8: 12673 | AE8: 33982837 | AF8: 15998817 | AG8: 12634260 | AH8: 0 | AI8: 3505792 | AJ8: 0 | AK8: =SUM(D8:AJ8) -> 2907546187
A9: 09 | B9: 1-1Q(1-3) | C9: 南山 | D9: 11482921 | E9: -4022 | F9: 47137294 | G9: 0 | H9: 2013246 | I9: 25552644 | J9: 0 | K9: 0 | L9: 0 | M9: 517904343 | N9: 0 | O9: 824896775 | P9: 15358 | Q9: 94484460 | R9: 5867698 | S9: 89642245 | T9: 206599248 | U9: 6547647 | V9: 41342401 | W9: 0 | X9: 2976491 | Y9: 0 | Z9: 46857206 | AA9: 214621549 | AB9: 13803733 | AC9: 198634361 | AD9: 10460280 | AE9: 7506592 | AF9: 4478421 | AG9: 81882942 | AH9: 0 | AI9: 1234342 | AJ9: 0 | AK9: =SUM(D9:AJ9) -> 2455938175
A10: 10 | B10: 1-1Q(1-3) | C10: 第一 | D10: 33953949 | E10: -716 | F10: 85342330 | G10: 0 | H10: 4283413 | I10: 76702314 | J10: 3033440 | K10: 3361403 | L10: -177532 | M10: 480185783 | N10: 3690046 | O10: 530857352 | P10: 17056555 | Q10: 107218866 | R10: 9058770 | S10: 39438638 | T10: 71480842 | U10: 3884200 | V10: 31878598 | W10: 373952 | X10: 3105206 | Y10: 0 | Z10: 13479552 | AA10: 127062786 | AB10: 42591382 | AC10: 24242527 | AD10: 377948 | AE10: 32089091 | AF10: 9467805 | AG10: 103224112 | AH10: 0 | AI10: 1035158 | AJ10: 111512 | AK10: =SUM(D10:AJ10) -> 1858409282
A11: 12 | B11: 1-1Q(1-3) | C11: 旺旺友聯 | D11: 31325806 | E11: -7033 | F11: 92119429 | G11: 0 | H11: 6016727 | I11: 24710748 | J11: 51455 | K11: 2850928 | L11: 0 | M11: 771268407 | N11: 32946200 | O11: 619248564 | P11: 203639068 | Q11: 147328574 | R11: 21720349 | S11: 36818720 | T11: 189503532 | U11: 5695249 | V11: 157643072 | W11: 447603 | X11: 8654064 | Y11: 0 | Z11: 13122695 | AA11: 328022470 | AB11: 46811939 | AC11: 33677387 | AD11: 118128 | AE11: 45561773 | AF11: 10497547 | AG11: 39799061 | AI11: 1468059 | AJ11: 20257 | AK11: =SUM(D11:AJ11) -> 2871080778
A12: 13 | B12: 1-1Q(1-3) | C12: 新光 | D12: 45364726 | E12: -3097 | F12: 278448470 | G12: 0 | H12: 20792738 | I12: 63772259 | J12: 55359882 | K12: 29158525 | L12: 7547695 | M12: 1284064565 | N12: 4781728 | O12: 1301149265 | P12: 70719580 | Q12: 242340040 | R12: 16375121 | S12: 134673201 | T12: 372638905 | U12: 61778701 | V12: 498219954 | W12: 724303 | X12: 5474092 | Y12: 44240 | Z12: 101877806 | AA12: 451134289 | AB12: 199024326 | AC12: 120923590 | AD12: 1034193 | AE12: 136319581 | AF12: 13802965 | AG12: 16369030 | AH12: 0 | AI12: 1590086 | AJ12: 465261 | AK12: =SUM(D12:AJ12) -> 5535966020
A13: 14 | B13: 1-1Q(1-3) | C13: 華南 | D13: 27967262 | E13: -5544 | F13: 70498745 | G13: 672 | H13: 2705890 | I13: 29097716 | J13: 1805123 | K13: 4156812 | L13: 32073 | M13: 1034066844 | N13: 27798091 | O13: 664173242 | P13: 189718885 | Q13: 146948902 | R13: 23672389 | S13: 50320873 | T13: 182360072 | U13: 13995805 | V13: 80029337 | W13: 492604 | X13: 13351184 | Y13: 36542 | Z13: 14128962 | AA13: 262905249 | AB13: 61321609 | AC13: 37638238 | AD13: 947909 | AE13: 53909118 | AF13: 19871569 | AG13: 21302506 | AH13: 0 | AI13: 1864083 | AJ13: 18359010 | AK13: =SUM(D13:AJ13) -> 3055471772
A14: 15 | B14: 1-1Q(1-3) | C14: 國泰世紀 | D14: 52677491 | E14: -4046 | F14: 136168995 | G14: 0 | H14: 5974953 | I14: 53753780 | J14: 5586098 | K14: 16134684 | L14: -589747 | M14: 1286647355 | N14: 25051023 | O14: 2500602738 | P14: 120263403 | Q14: 279406530 | R14: 23042688 | S14: 322665258 | T14: 549296894 | U14: 30847297 | V14: 80092510 | W14: 710709 | X14: 9545075 | Y14: -104547 | Z14: 7047764 | AA14: 852645002 | AB14: 85731162 | AC14: 362185704 | AD14: 0 | AE14: 67574553 | AF14: 16161160 | AG14: 144020039 | AH14: 0 | AI14: 5835731 | AJ14: 0 | AK14: =SUM(D14:AJ14) -> 7038970256
A15: 17 | B15: 1-1Q(1-3) | C15: 新安東京海上 | D15: 25316820 | E15: 0 | F15: 95465894 | G15: 0 | H15: 12027563 | I15: 33305887 | J15: 8825 | K15: 785673 | L15: 0 | M15: 1226496455 | N15: 150499014 | O15: 1630705434 | P15: 407436715 | Q15: 199575690 | R15: 31761870 | S15: 73101256 | T15: 138531313 | U15: 9783393 | V15: 58095854 | W15: 1617116 | X15: 9721727 | Y15: 0 | Z15: 82587689 | AA15: 312034568 | AB15: 49245419 | AC15: 56743772 | AD15: 5797035 | AE15: 42499159 | AF15: 7755364 | AG15: 20985132 | AH15: 0 | AI15: 1367724 | AJ15: 224867 | AK15: =SUM(D15:AJ15) -> 4683477228
A16: 18 | B16: 1-1Q(1-3) | C16: 中國信託 | D16: 34722722 | E16: 0 | F16: 1996927 | G16: 0 | H16: 196049 | I16: 1664402 | J16: 0 | K16: 0 | L16: 0 | M16: 127408578 | N16: 2925387 | O16: 196418985 | P16: 19670278 | Q16: 31632527 | R16: 3564298 | S16: 24044229 | T16: 48532328 | U16: 1552619 | V16: 34666979 | W16: 86007 | X16: 2625240 | Y16: 0 | Z16: 10886016 | AA16: 53214533 | AB16: 8508591 | AC16: 55057926 | AD16: 706034 | AE16: 4202293 | AF16: 9496265 | AG16: 17502424 | AH16: 0 | AI16: 468785 | AJ16: 0 | AK16: =SUM(D16:AJ16) -> 691750422
A17: 28 | B17: 1-1Q(1-3) | C17: 裕利安宜 | D17: 0 | E17: 0 | F17: 0 | G17: 0 | H17: 0 | I17: 0 | J17: 0 | K17: 0 | L17: 0 | M17: 0 | N17: 0 | O17: 0 | P17: 0 | Q17: 0 | R17: 0 | S17: 0 | T17: 0 | U17: 0 | V17: 0 | W17: 0 | X17: 0 | Y17: -45098954 | Z17: 0 | AA17: 0 | AB17: 0 | AC17: 0 | AD17: 0 | AE17: 0 | AF17: 0 | AG17: 0 | AH17: 0 | AI17: 0 | AJ17: 0 | AK17: =SUM(D17:AJ17) -> -45098954
A18: 29 | B18: 1-1Q(1-3) | C18: 美國國際 | D18: 0 | E18: 0 | F18: 8599953 | G18: 0 | H18: 225309 | I18: 15826145 | J18: 372119 | K18: 0 | L18: 0 | M18: 0 | N18: 0 | O18: 0 | P18: 0 | Q18: 0 | R18: 0 | S18: 0 | T18: 23539090 | U18: 9541614 | V18: 980889 | W18: 0 | X18: 234647 | Y18: 8172832 | Z18: 35066840 | AA18: 0 | AB18: 7779659 | AC18: 0 | AD18: 161487 | AE18: 4604355 | AF18: 0 | AG18: 0 | AH18: 0 | AI18: 0 | AJ18: 2637448 | AK18: =SUM(D18:AJ18) -> 117742387
A19: 32 | B19: 1-1Q(1-3) | C19: 美商安達 | D19: 5612248 | E19: 0 | F19: 8330467 | G19: 0 | H19: 2569238 | I19: 15807526 | J19: 0 | K19: 0 | L19: 0 | M19: 0 | N19: 0 | O19: 0 | P19: 0 | Q19: 1143291 | R19: 193238 | S19: 900804 | T19: 206234819 | U19: 53284169 | V19: 55517506 | W19: 0 | X19: 5777 | Y19: 0 | Z19: 631261138 | AA19: 58161774 | AB19: 8551978 | AC19: 10564501 | AD19: -1319436 | AE19: 21888857 | AF19: 2621577 | AG19: 39785230 | AH19: 0 | AI19: 24314 | AJ19: 25007940 | AK19: =SUM(D19:AJ19) -> 1146146956
A20: 46 | B20: 1-1Q(1-3) | C20: 法國巴黎 | D20: 3298147 | E20: 0 | F20: 0 | G20: 0 | H20: 0 | I20: 0 | J20: 0 | K20: 0 | L20: 0 | M20: 0 | N20: 0 | O20: 0 | P20: 0 | Q20: 0 | R20: 0 | S20: 0 | T20: 0 | U20: 0 | V20: 0 | W20: 0 | X20: 0 | Y20: 0 | Z20: 0 | AA20: 16588832 | AB20: 0 | AC20: 0 | AD20: 0 | AE20: 0 | AF20: 1912223 | AG20: 5500350 | AH20: 0 | AI20: 0 | AJ20: 0 | AK20: =SUM(D20:AJ20) -> 27299552
A21: 47 | B21: 1-1Q(1-3) | C21: 科法斯 | D21: 0 | E21: 0 | F21: 0 | G21: 0 | H21: 0 | I21: 0 | J21: 0 | K21: 0 | L21: 0 | M21: 0 | N21: 0 | O21: 0 | P21: 0 | Q21: 0 | R21: 0 | S21: 0 | T21: 0 | U21: 0 | V21: 0 | W21: 0 | X21: 0 | Y21: 7553939 | Z21: 0 | AA21: 0 | AB21: 0 | AC21: 0 | AD21: 0 | AE21: 0 | AF21: 0 | AG21: 0 | AH21: 0 | AI21: 0 | AJ21: 0 | AK21: =SUM(D21:AJ21) -> 7553939
B22: 1-1Q(1-3) | C22: 小計 | D22: =SUBTOTAL(9,D3:D21) -> 5.692052e+08 | E22: =SUBTOTAL(9,E3:E21) -> -65438 | F22: =SUBTOTAL(9,F3:F21) -> 1556074587 | G22: =SUBTOTAL(9,G3:G21) -> -799 | H22: =SUBTOTAL(9,H3:H21) -> 2.1802789e+08 | I22: =SUBTOTAL(9,I3:I21) -> 7.0815659e+08 | J22: =SUBTOTAL(9,J3:J21) -> 1.0984631e+08 | K22: =SUBTOTAL(9,K3:K21) -> 1.0120545e+08 | ... AK22: =SUBTOTAL(9,AK3:AK21) -> 54058837148
A23: 01 | B23: 1-2Q(1-6) | C23: 台產 | AK23: =SUM(D23:AJ23) -> 0
A24: 02 | B24: 1-2Q(1-6) | C24: 兆豐 | AK24: =SUM(D24:AJ24) -> 0
A25: 05 | B25: 1-2Q(1-6) | C25: 富邦 | AK25: =SUM(D25:AJ25) -> 0
A26: 06 | B26: 1-2Q(1-6) | C26: 和泰 | AK26: =SUM(D26:AJ26) -> 0
A27: 07 | B27: 1-2Q(1-6) | C27: 泰安 | AK27: =SUM(D27:AJ27) -> 0
A28: 08 | B28: 1-2Q(1-6) | C28: 明台 | AK28: =SUM(D28:AJ28) -> 0
A29: 09 | B29: 1-2Q(1-6) | C29: 南山 | AK29: =SUM(D29:AJ29) -> 0
A30: 10 | B30: 1-2Q(1-6) | C30: 第一 | AK30: =SUM(D30:AJ30) -> 0
A31: 12 | B31: 1-2Q(1-6) | C31: 旺旺友聯 | AK31: =SUM(D31:AJ31) -> 0
A32: 13 | B32: 1-2Q(1-6) | C32: 新光 | AK32: =SUM(D32:AJ32) -> 0
A33: 14 | B33: 1-2Q(1-6) | C33: 華南 | AK33: =SUM(D33:AJ33) -> 0
A34: 15 | B34: 1-2Q(1-6) | C34: 國泰世紀 | AK34: =SUM(D34:AJ34) -> 0
A35: 17 | B35: 1-2Q(1-6) | C35: 新安東京海上 | AK35: =SUM(D35:AJ35) -> 0
A36: 18 | B36: 1-2Q(1-6) | C36: 中國信託 | AK36: =SUM(D36:AJ36) -> 0
A37: 28 | B37: 1-2Q(1-6) | C37: 裕利安宜 | AK37: =SUM(D37:AJ37) -> 0
A38: 29 | B38: 1-2Q(1-6) | C38: 美國國際 | AK38: =SUM(D38:AJ38) -> 0
A39: 32 | B39: 1-2Q(1-6) | C39: 美商安達 | AK39: =SUM(D39:AJ39) -> 0
A40: 46 | B40: 1-2Q(1-6) | C40: 法國巴黎 | AK40: =SUM(D40:AJ40) -> 0
...

Sheet 115自留總累
A1: 115年度第1季(1-3月份)各保險公司自留保費統計總表
V2: 單位:新台幣元
G3: 汽車險 | L3: 意外險 | V3: 比較
A4: 代號 | B4: 月份 | C4: 公司別/險種 | D4: 火險 | E4: 水險 | F4: 航空 | G4: 車體損失險 | H4: 任意責任險 | I4: 強制責任險 | L4: 責任險 | M4: 工程險 | N4: 信用保證 | O4: 其他財產 | P4: 傷害險 | Q4: 天災險 | R4: 健康險 | S4: 國外分進 | T4: 115年度 | U4: 114年度 | V4: 成長率
I5: 汽車 | J5: 機車 | K5: 二輪電動 | O5: 責任保險 | T5: 合計 | U5: 合計 | V5: %
A6: 01 | B6: 1-1Q(1-3) | C6: 台產 | D6: =SUM('115自留(季)'!D3:G3) -> 88915729 | E6: =SUM('115自留(季)'!H3:K3) -> 38555219 | F6: =+'115自留(季)'!L3 -> 820658 | G6: =SUM('115自留(季)'!M3:N3) -> 277093445 | H6: =SUM('115自留(季)'!O3:P3) -> 671762219 | I6: =SUM('115自留(季)'!Q3:R3) -> 108198044 | J6: =+'115自留(季)'!S3 -> 55237289 | K6: ='115自留(季)'!AI3 -> 1006055 | L6: =SUM('115自留(季)'!T3:U3) -> 63498697 | M6: =+'115自留(季)'!V3 -> 46911029 | N6: =SUM('115自留(季)'!X3:Y3) -> 2334390 | O6: =+'115自留(季)'!W3+'115自留(季)'!Z3+'115自留(季)'!AC3+'115自留(季)'!AD3 -> 67707238 | P6: =+'115自留(季)'!AA3 -> 158015657 | Q6: =+'115自留(季)'!AB3+'115自留(季)'!AE3+'115自留(季)'!AF3 -> 60013932 | R6: =+'115自留(季)'!AG3+'115自留(季)'!AH3 -> 36516642 | S6: =+'115自留(季)'!AJ3 -> 57202 | T6: =SUM(D6:S6) -> 1676643445 | U6: 1739709910 | V6: =IF(U6=0,"",((T6/U6)-1)) -> -0.036251139
A7: 02 | B7: 1-1Q(1-3) | C7: 兆豐 | D7: =SUM('115自留(季)'!D4:G4) -> 1.3146893e+08 | E7: =SUM('115自留(季)'!H4:K4) -> 48062955 | F7: =+'115自留(季)'!L4 -> 12509798 | G7: =SUM('115自留(季)'!M4:N4) -> 4.2323422e+08 | H7: =SUM('115自留(季)'!O4:P4) -> 3.6772653e+08 | I7: =SUM('115自留(季)'!Q4:R4) -> 65461562 | J7: =+'115自留(季)'!S4 -> 21690368 | K7: ='115自留(季)'!AI4 -> 392313 | L7: =SUM('115自留(季)'!T4:U4) -> 1.261711e+08 | M7: =+'115自留(季)'!V4 -> 120183253 | N7: =SUM('115自留(季)'!X4:Y4) -> 2939675.8 | O7: =+'115自留(季)'!W4+'115自留(季)'!Z4+'115自留(季)'!AC4+'115自留(季)'!AD4 -> 47292757 | P7: =+'115自留(季)'!AA4 -> 98670081 | Q7: =+'115自留(季)'!AB4+'115自留(季)'!AE4+'115自留(季)'!AF4 -> 1.3738493e+08 | R7: =+'115自留(季)'!AG4+'115自留(季)'!AH4 -> 23804367 | S7: =+'115自留(季)'!AJ4 -> 43495460 | T7: =SUM(D7:S7) -> 1670488295 | U7: 1697776843 | V7: =IF(U7=0,"",((T7-U7)/U7)) -> -0.016073107
A8: 05 | B8: 1-1Q(1-3) | C8: 富邦 | D8: =SUM('115自留(季)'!D5:G5) -> 3.2627677e+08 | E8: =SUM('115自留(季)'!H5:K5) -> 3.2404619e+08 | F8: =+'115自留(季)'!L5 -> 2729734.6 | G8: =SUM('115自留(季)'!M5:N5) -> 1895573598 | H8: =SUM('115自留(季)'!O5:P5) -> 3651293857 | I8: =SUM('115自留(季)'!Q5:R5) -> 539614399 | J8: =+'115自留(季)'!S5 -> 642426561 | K8: ='115自留(季)'!AI5 -> 32675497 | L8: =SUM('115自留(季)'!T5:U5) -> 1187615402 | M8: =+'115自留(季)'!V5 -> 2.2747526e+08 | N8: =SUM('115自留(季)'!X5:Y5) -> 17041945 | O8: =+'115自留(季)'!W5+'115自留(季)'!Z5+'115自留(季)'!AC5+'115自留(季)'!AD5 -> 7.2932383e+08 | P8: =+'115自留(季)'!AA5 -> 2054719954 | Q8: =+'115自留(季)'!AB5+'115自留(季)'!AE5+'115自留(季)'!AF5 -> 2.3952932e+08 | R8: =+'115自留(季)'!AG5+'115自留(季)'!AH5 -> 827747829 | S8: =+'115自留(季)'!AJ5 -> 89714652 | T8: =SUM(D8:S8) -> 12787804788 | U8: 1.2382328e+10 | V8: =IF(U8=0,"",((T8-U8)/U8)) -> 0.032746374
A9: 06 | B9: 1-1Q(1-3) | C9: 和泰 | D9: =SUM('115自留(季)'!D6:G6) -> 121913602 | E9: =SUM('115自留(季)'!H6:K6) -> 56595572 | F9: =+'115自留(季)'!L6 -> 26 | G9: =SUM('115自留(季)'!M6:N6) -> 1389445652 | H9: =SUM('115自留(季)'!O6:P6) -> 814930182 | I9: =SUM('115自留(季)'!Q6:R6) -> 124705135 | J9: =+'115自留(季)'!S6 -> 18370804 | K9: ='115自留(季)'!AI6 -> 375219 | L9: =SUM('115自留(季)'!T6:U6) -> 137842964 | M9: =+'115自留(季)'!V6 -> 112365322 | N9: =SUM('115自留(季)'!X6:Y6) -> 1699408 | O9: =+'115自留(季)'!W6+'115自留(季)'!Z6+'115自留(季)'!AC6+'115自留(季)'!AD6 -> 8670420 | P9: =+'115自留(季)'!AA6 -> 181051884 | Q9: =+'115自留(季)'!AB6+'115自留(季)'!AE6+'115自留(季)'!AF6 -> 111954096 | R9: =+'115自留(季)'!AG6+'115自留(季)'!AH6 -> 42425346 | S9: =+'115自留(季)'!AJ6 -> 2173666 | T9: =SUM(D9:S9) -> 3124519298 | U9: 2981511602 | V9: =IF(U9=0,"",((T9-U9)/U9)) -> 0.04796483
A10: 07 | B10: 1-1Q(1-3) | C10: 泰安 | D10: =SUM('115自留(季)'!D7:G7) -> 190922921 | E10: =SUM('115自留(季)'!H7:K7) -> 55286627 | F10: =+'115自留(季)'!L7 -> 0 | G10: =SUM('115自留(季)'!M7:N7) -> 616800935 | H10: =SUM('115自留(季)'!O7:P7) -> 713637716 | I10: =SUM('115自留(季)'!Q7:R7) -> 140264323 | J10: =+'115自留(季)'!S7 -> 64447852 | K10: ='115自留(季)'!AI7 -> 2429172 | L10: =SUM('115自留(季)'!T7:U7) -> 188800017 | M10: =+'115自留(季)'!V7 -> 121634108 | N10: =SUM('115自留(季)'!X7:Y7) -> 1281043 | O10: =+'115自留(季)'!W7+'115自留(季)'!Z7+'115自留(季)'!AC7+'115自留(季)'!AD7 -> 60285633 | P10: =+'115自留(季)'!AA7 -> 209063283 | Q10: =+'115自留(季)'!AB7+'115自留(季)'!AE7+'115自留(季)'!AF7 -> 60247983 | R10: =+'115自留(季)'!AG7+'115自留(季)'!AH7 -> 22025709 | S10: =+'115自留(季)'!AJ7 -> 0 | T10: =SUM(D10:S10) -> 2447127322 | U10: 2336312172 | V10: =IF(U10=0,"",((T10-U10)/U10)) -> 0.047431654
A11: 08 | B11: 1-1Q(1-3) | C11: 明台 | D11: =SUM('115自留(季)'!D8:G8) -> 169908798 | E11: =SUM('115自留(季)'!H8:K8) -> 95026159 | F11: =+'115自留(季)'!L8 -> -29507 | G11: =SUM('115自留(季)'!M8:N8) -> 814986077 | H11: =SUM('115自留(季)'!O8:P8) -> 892901355 | I11: =SUM('115自留(季)'!Q8:R8) -> 176718652 | J11: =+'115自留(季)'!S8 -> 62881172 | K11: ='115自留(季)'!AI8 -> 3505792 | L11: =SUM('115自留(季)'!T8:U8) -> 270835764 | M11: =+'115自留(季)'!V8 -> 84204258 | N11: =SUM('115自留(季)'!X8:Y8) -> 129574 | O11: =+'115自留(季)'!W8+'115自留(季)'!Z8+'115自留(季)'!AC8+'115自留(季)'!AD8 -> 90942727 | P11: =+'115自留(季)'!AA8 -> 161237056 | Q11: =+'115自留(季)'!AB8+'115自留(季)'!AE8+'115自留(季)'!AF8 -> 71664050 | R11: =+'115自留(季)'!AG8+'115自留(季)'!AH8 -> 12634260 | S11: =+'115自留(季)'!AJ8 -> 0 | T11: =SUM(D11:S11) -> 2907546187 | U11: 2875372542 | V11: =IF(U11=0,"",((T11-U11)/U11)) -> 0.011189383
A12: 09 | B12: 1-1Q(1-3) | C12: 南山 | D12: =SUM('115自留(季)'!D9:G9) -> 58616193 | E12: =SUM('115自留(季)'!H9:K9) -> 27565890 | F12: =+'115自留(季)'!L9 -> 0 | G12: =SUM('115自留(季)'!M9:N9) -> 517904343 | H12: =SUM('115自留(季)'!O9:P9) -> 824912133 | I12: =SUM('115自留(季)'!Q9:R9) -> 100352158 | J12: =+'115自留(季)'!S9 -> 89642245 | K12: ='115自留(季)'!AI9 -> 1234342 | L12: =SUM('115自留(季)'!T9:U9) -> 213146895 | M12: =+'115自留(季)'!V9 -> 41342401 | N12: =SUM('115自留(季)'!X9:Y9) -> 2976491 | O12: =+'115自留(季)'!W9+'115自留(季)'!Z9+'115自留(季)'!AC9+'115自留(季)'!AD9 -> 255951847 | P12: =+'115自留(季)'!AA9 -> 214621549 | Q12: =+'115自留(季)'!AB9+'115自留(季)'!AE9+'115自留(季)'!AF9 -> 25788746 | R12: =+'115自留(季)'!AG9+'115自留(季)'!AH9 -> 81882942 | S12: =+'115自留(季)'!AJ9 -> 0 | T12: =SUM(D12:S12) -> 2455938175 | U12: 2205039907 | V12: =IF(U12=0,"",((T12-U12)/U12)) -> 0.113784
A13: 10 | B13: 1-1Q(1-3) | C13: 第一 | D13: =SUM('115自留(季)'!D10:G10) -> 119295563 | E13: =SUM('115自留(季)'!H10:K10) -> 87380570 | F13: =+'115自留(季)'!L10 -> -177532 | G13: =SUM('115自留(季)'!M10:N10) -> 483875829 | H13: =SUM('115自留(季)'!O10:P10) -> 547913907 | I13: =SUM('115自留(季)'!Q10:R10) -> 116277636 | J13: =+'115自留(季)'!S10 -> 39438638 | K13: ='115自留(季)'!AI10 -> 1035158 | L13: =SUM('115自留(季)'!T10:U10) -> 75365042 | M13: =+'115自留(季)'!V10 -> 31878598 | N13: =SUM('115自留(季)'!X10:Y10) -> 3105206 | O13: =+'115自留(季)'!W10+'115自留(季)'!Z10+'115自留(季)'!AC10+'115自留(季)'!AD10 -> 38473979 | P13: =+'115自留(季)'!AA10 -> 127062786 | Q13: =+'115自留(季)'!AB10+'115自留(季)'!AE10+'115自留(季)'!AF10 -> 84148278 | R13: =+'115自留(季)'!AG10+'115自留(季)'!AH10 -> 103224112 | S13: =+'115自留(季)'!AJ10 -> 111512 | T13: =SUM(D13:S13) -> 1858409282 | U13: 1855413291 | V13: =IF(U13=0,"",((T13-U13)/U13)) -> 0.0016147297
A14: 12 | B14: 1-1Q(1-3) | C14: 旺旺友聯 | D14: =SUM('115自留(季)'!D11:G11) -> 123438202 | E14: =SUM('115自留(季)'!H11:K11) -> 33629858 | F14: =+'115自留(季)'!L11 -> 0 | G14: =SUM('115自留(季)'!M11:N11) -> 804214607 | H14: =SUM('115自留(季)'!O11:P11) -> 822887632 | I14: =SUM('115自留(季)'!Q11:R11) -> 169048923 | J14: =+'115自留(季)'!S11 -> 36818720 | K14: ='115自留(季)'!AI11 -> 1468059 | L14: =SUM('115自留(季)'!T11:U11) -> 195198781 | M14: =+'115自留(季)'!V11 -> 157643072 | N14: =SUM('115自留(季)'!X11:Y11) -> 8654064 | O14: =+'115自留(季)'!W11+'115自留(季)'!Z11+'115自留(季)'!AC11+'115自留(季)'!AD11 -> 47365813 | P14: =+'115自留(季)'!AA11 -> 328022470 | Q14: =+'115自留(季)'!AB11+'115自留(季)'!AE11+'115自留(季)'!AF11 -> 102871259 | R14: =+'115自留(季)'!AG11+'115自留(季)'!AH11 -> 39799061 | S14: =+'115自留(季)'!AJ11 -> 20257 | T14: =SUM(D14:S14) -> 2871080778 | U14: 2805142720 | V14: =IF(U14=0,"",((T14-U14)/U14)) -> 0.023506133
A15: 13 | B15: 1-1Q(1-3) | C15: 新光 | D15: =SUM('115自留(季)'!D12:G12) -> 323810099 | E15: =SUM('115自留(季)'!H12:K12) -> 169083404 | F15: =+'115自留(季)'!L12 -> 7547695 | G15: =SUM('115自留(季)'!M12:N12) -> 1288846293 | H15: =SUM('115自留(季)'!O12:P12) -> 1371868845 | I15: =SUM('115自留(季)'!Q12:R12) -> 258715161 | J15: =+'115自留(季)'!S12 -> 134673201 | K15: ='115自留(季)'!AI12 -> 1590086 | L15: =SUM('115自留(季)'!T12:U12) -> 434417606 | M15: =+'115自留(季)'!V12 -> 498219954 | N15: =SUM('115自留(季)'!X12:Y12) -> 5518332 | O15: =+'115自留(季)'!W12+'115自留(季)'!Z12+'115自留(季)'!AC12+'115自留(季)'!AD12 -> 224559892 | P15: =+'115自留(季)'!AA12 -> 451134289 | Q15: =+'115自留(季)'!AB12+'115自留(季)'!AE12+'115自留(季)'!AF12 -> 349146872 | R15: =+'115自留(季)'!AG12+'115自留(季)'!AH12 -> 16369030 | S15: =+'115自留(季)'!AJ12 -> 465261 | T15: =SUM(D15:S15) -> 5535966020 | U15: 5470041239 | V15: =IF(U15=0,"",((T15-U15)/U15)) -> 0.012051971
A16: 14 | B16: 1-1Q(1-3) | C16: 華南 | D16: =SUM('115自留(季)'!D13:G13) -> 98461135 | E16: =SUM('115自留(季)'!H13:K13) -> 37765541 | F16: =+'115自留(季)'!L13 -> 32073 | G16: =SUM('115自留(季)'!M13:N13) -> 1061864935 | H16: =SUM('115自留(季)'!O13:P13) -> 853892127 | I16: =SUM('115自留(季)'!Q13:R13) -> 170621291 | J16: =+'115自留(季)'!S13 -> 50320873 | K16: ='115自留(季)'!AI13 -> 1864083 | L16: =SUM('115自留(季)'!T13:U13) -> 196355877 | M16: =+'115自留(季)'!V13 -> 80029337 | N16: =SUM('115自留(季)'!X13:Y13) -> 13387726 | O16: =+'115自留(季)'!W13+'115自留(季)'!Z13+'115自留(季)'!AC13+'115自留(季)'!AD13 -> 53207713 | P16: =+'115自留(季)'!AA13 -> 262905249 | Q16: =+'115自留(季)'!AB13+'115自留(季)'!AE13+'115自留(季)'!AF13 -> 135102296 | R16: =+'115自留(季)'!AG13+'115自留(季)'!AH13 -> 21302506 | S16: =+'115自留(季)'!AJ13 -> 18359010 | T16: =SUM(D16:S16) -> 3055471772 | U16: 2890247076 | V16: =IF(U16=0,"",((T16-U16)/U16)) -> 0.057166288
A17: 15 | B17: 1-1Q(1-3) | C17: 國泰世紀 | D17: =SUM('115自留(季)'!D14:G14) -> 188842440 | E17: =SUM('115自留(季)'!H14:K14) -> 81449515 | F17: =+'115自留(季)'!L14 -> -589747 | G17: =SUM('115自留(季)'!M14:N14) -> 1311698378 | H17: =SUM('115自留(季)'!O14:P14) -> 2620866141 | I17: =SUM('115自留(季)'!Q14:R14) -> 302449218 | J17: =+'115自留(季)'!S14 -> 322665258 | K17: ='115自留(季)'!AI14 -> 5835731 | L17: =SUM('115自留(季)'!T14:U14) -> 580144191 | M17: =+'115自留(季)'!V14 -> 80092510 | N17: =SUM('115自留(季)'!X14:Y14) -> 9440528 | O17: =+'115自留(季)'!W14+'115自留(季)'!Z14+'115自留(季)'!AC14+'115自留(季)'!AD14 -> 369944177 | P17: =+'115自留(季)'!AA14 -> 852645002 | Q17: =+'115自留(季)'!AB14+'115自留(季)'!AE14+'115自留(季)'!AF14 -> 169466875 | R17: =+'115自留(季)'!AG14+'115自留(季)'!AH14 -> 144020039 | S17: =+'115自留(季)'!AJ14 -> 0 | T17: =SUM(D17:S17) -> 7038970256 | U17: 6750796043 | V17: =IF(U17=0,"",((T17-U17)/U17)) -> 0.042687442
A18: 17 | B18: 1-1Q(1-3) | C18: 新安東京海上 | D18: =SUM('115自留(季)'!D15:G15) -> 120782714 | E18: =SUM('115自留(季)'!H15:K15) -> 46127948 | F18: =+'115自留(季)'!L15 -> 0 | G18: =SUM('115自留(季)'!M15:N15) -> 1376995469 | H18: =SUM('115自留(季)'!O15:P15) -> 2038142149 | I18: =SUM('115自留(季)'!Q15:R15) -> 231337560 | J18: =+'115自留(季)'!S15 -> 73101256 | K18: ='115自留(季)'!AI15 -> 1367724 | L18: =SUM('115自留(季)'!T15:U15) -> 148314706 | M18: =+'115自留(季)'!V15 -> 58095854 | N18: =SUM('115自留(季)'!X15:Y15) -> 9721727 | O18: =+'115自留(季)'!W15+'115自留(季)'!Z15+'115自留(季)'!AC15+'115自留(季)'!AD15 -> 146745612 | P18: =+'115自留(季)'!AA15 -> 312034568 | Q18: =+'115自留(季)'!AB15+'115自留(季)'!AE15+'115自留(季)'!AF15 -> 99499942 | R18: =+'115自留(季)'!AG15+'115自留(季)'!AH15 -> 20985132 | S18: =+'115自留(季)'!AJ15 -> 224867 | T18: =SUM(D18:S18) -> 4683477228 | U18: 4606500775 | V18: =IF(U18=0,"",((T18-U18)/U18)) -> 0.016710396
A19: 18 | B19: 1-1Q(1-3) | C19: 中國信託 | D19: =SUM('115自留(季)'!D16:G16) -> 36719649 | E19: =SUM('115自留(季)'!H16:K16) -> 1860451 | F19: =+'115自留(季)'!L16 -> 0 | G19: =SUM('115自留(季)'!M16:N16) -> 130333965 | H19: =SUM('115自留(季)'!O16:P16) -> 216089263 | I19: =SUM('115自留(季)'!Q16:R16) -> 35196825 | J19: =+'115自留(季)'!S16 -> 24044229 | K19: ='115自留(季)'!AI16 -> 468785 | L19: =SUM('115自留(季)'!T16:U16) -> 50084947 | M19: =+'115自留(季)'!V16 -> 34666979 | N19: =SUM('115自留(季)'!X16:Y16) -> 2625240 | O19: =+'115自留(季)'!W16+'115自留(季)'!Z16+'115自留(季)'!AC16+'115自留(季)'!AD16 -> 66735983 | P19: =+'115自留(季)'!AA16 -> 53214533 | Q19: =+'115自留(季)'!AB16+'115自留(季)'!AE16+'115自留(季)'!AF16 -> 22207149 | R19: =+'115自留(季)'!AG16+'115自留(季)'!AH16 -> 17502424 | S19: =+'115自留(季)'!AJ16 -> 0 | T19: =SUM(D19:S19) -> 691750422 | U19: 608829767 | V19: =IF(U19=0,"",((T19-U19)/U19)) -> 0.13619678
A20: 28 | B20: 1-1Q(1-3) | C20: 裕利安宜 | D20: =SUM('115自留(季)'!D17:G17) -> 0 | E20: =SUM('115自留(季)'!H17:K17) -> 0 | F20: =+'115自留(季)'!L17 -> 0 | G20: =SUM('115自留(季)'!M17:N17) -> 0 | H20: =SUM('115自留(季)'!O17:P17) -> 0 | I20: =SUM('115自留(季)'!Q17:R17) -> 0 | J20: =+'115自留(季)'!S17 -> 0 | K20: ='115自留(季)'!AI17 -> 0 | L20: =SUM('115自留(季)'!T17:U17) -> 0 | M20: =+'115自留(季)'!V17 -> 0 | N20: =SUM('115自留(季)'!X17:Y17) -> -45098954 | O20: =+'115自留(季)'!W17+'115自留(季)'!Z17+'115自留(季)'!AC17+'115自留(季)'!AD17 -> 0 | P20: =+'115自留(季)'!AA17 -> 0 | Q20: =+'115自留(季)'!AB17+'115自留(季)'!AE17+'115自留(季)'!AF17 -> 0 | R20: =+'115自留(季)'!AG17+'115自留(季)'!AH17 -> 0 | S20: =+'115自留(季)'!AJ17 -> 0 | T20: =SUM(D20:S20) -> -45098954 | U20: -82032243 | V20: =IF(U20=0,"",((T20-U20)/U20)) -> -0.45022893
A21: 29 | B21: 1-1Q(1-3) | C21: 美國國際 | D21: =SUM('115自留(季)'!D18:G18) -> 8599953 | E21: =SUM('115自留(季)'!H18:K18) -> 16423573 | F21: =+'115自留(季)'!L18 -> 0 | G21: =SUM('115自留(季)'!M18:N18) -> 0 | H21: =SUM('115自留(季)'!O18:P18) -> 0 | I21: =SUM('115自留(季)'!Q18:R18) -> 0 | J21: =+'115自留(季)'!S18 -> 0 | K21: ='115自留(季)'!AI18 -> 0 | L21: =SUM('115自留(季)'!T18:U18) -> 33080704 | M21: =+'115自留(季)'!V18 -> 980889 | N21: =SUM('115自留(季)'!X18:Y18) -> 8407479 | O21: =+'115自留(季)'!W18+'115自留(季)'!Z18+'115自留(季)'!AC18+'115自留(季)'!AD18 -> 35228327 | P21: =+'115自留(季)'!AA18 -> 0 | Q21: =+'115自留(季)'!AB18+'115自留(季)'!AE18+'115自留(季)'!AF18 -> 12384014 | R21: =+'115自留(季)'!AG18+'115自留(季)'!AH18 -> 0 | S21: =+'115自留(季)'!AJ18 -> 2637448 | T21: =SUM(D21:S21) -> 117742387 | U21: 146913958 | V21: =IF(U21=0,"",((T21-U21)/U21)) -> -0.19856228
A22: 32 | B22: 1-1Q(1-3) | C22: 美商安達 | D22: =SUM('115自留(季)'!D19:G19) -> 13942715 | E22: =SUM('115自留(季)'!H19:K19) -> 18376764 | F22: =+'115自留(季)'!L19 -> 0 | G22: =SUM('115自留(季)'!M19:N19) -> 0 | H22: =SUM('115自留(季)'!O19:P19) -> 0 | I22: =SUM('115自留(季)'!Q19:R19) -> 1336529 | J22: =+'115自留(季)'!S19 -> 900804 | K22: ='115自留(季)'!AI19 -> 24314 | L22: =SUM('115自留(季)'!T19:U19) -> 259518988 | M22: =+'115自留(季)'!V19 -> 55517506 | N22: =SUM('115自留(季)'!X19:Y19) -> 5777 | O22: =+'115自留(季)'!W19+'115自留(季)'!Z19+'115自留(季)'!AC19+'115自留(季)'!AD19 -> 640506203 | P22: =+'115自留(季)'!AA19 -> 58161774 | Q22: =+'115自留(季)'!AB19+'115自留(季)'!AE19+'115自留(季)'!AF19 -> 33062412 | R22: =+'115自留(季)'!AG19+'115自留(季)'!AH19 -> 39785230 | S22: =+'115自留(季)'!AJ19 -> 25007940 | T22: =SUM(D22:S22) -> 1146146956 | U22: 1195539507 | V22: =IF(U22=0,"",((T22-U22)/U22)) -> -0.041314027
A23: 46 | B23: 1-1Q(1-3) | C23: 法國巴黎 | D23: =SUM('115自留(季)'!D20:G20) -> 3298147 | E23: =SUM('115自留(季)'!H20:K20) -> 0 | F23: =+'115自留(季)'!L20 -> 0 | G23: =SUM('115自留(季)'!M20:N20) -> 0 | H23: =SUM('115自留(季)'!O20:P20) -> 0 | I23: =SUM('115自留(季)'!Q20:R20) -> 0 | J23: =+'115自留(季)'!S20 -> 0 | K23: ='115自留(季)'!AI20 -> 0 | L23: =SUM('115自留(季)'!T20:U20) -> 0 | M23: =+'115自留(季)'!V20 -> 0 | N23: =SUM('115自留(季)'!X20:Y20) -> 0 | O23: =+'115自留(季)'!W20+'115自留(季)'!Z20+'115自留(季)'!AC20+'115自留(季)'!AD20 -> 0 | P23: =+'115自留(季)'!AA20 -> 16588832 | Q23: =+'115自留(季)'!AB20+'115自留(季)'!AE20+'115自留(季)'!AF20 -> 1912223 | R23: =+'115自留(季)'!AG20+'115自留(季)'!AH20 -> 5500350 | S23: =+'115自留(季)'!AJ20 -> 0 | T23: =SUM(D23:S23) -> 27299552 | U23: 29849084 | V23: =IF(U23=0,"",((T23-U23)/U23)) -> -0.085414078
A24: 47 | B24: 1-1Q(1-3) | C24: 科法斯 | D24: =SUM('115自留(季)'!D21:G21) -> 0 | E24: =SUM('115自留(季)'!H21:K21) -> 0 | F24: =+'115自留(季)'!L21 -> 0 | G24: =SUM('115自留(季)'!M21:N21) -> 0 | H24: =SUM('115自留(季)'!O21:P21) -> 0 | I24: =SUM('115自留(季)'!Q21:R21) -> 0 | J24: =+'115自留(季)'!S21 -> 0 | K24: ='115自留(季)'!AI21 -> 0 | L24: =SUM('115自留(季)'!T21:U21) -> 0 | M24: =+'115自留(季)'!V21 -> 0 | N24: =SUM('115自留(季)'!X21:Y21) -> 7553939 | O24: =+'115自留(季)'!W21+'115自留(季)'!Z21+'115自留(季)'!AC21+'115自留(季)'!AD21 -> 0 | P24: =+'115自留(季)'!AA21 -> 0 | Q24: =+'115自留(季)'!AB21+'115自留(季)'!AE21+'115自留(季)'!AF21 -> 0 | R24: =+'115自留(季)'!AG21+'115自留(季)'!AH21 -> 0 | S24: =+'115自留(季)'!AJ21 -> 0 | T24: =SUM(D24:S24) -> 7553939 | U24: -870044 | V24: =IF(U24=0,"",((T24-U24)/-U24)) -> 9.6822494
B25: 1-1Q(1-3) | C25: 小計 | D25: =SUBTOTAL(9,D6:D24) -> 2125213551 | E25: =SUBTOTAL(9,E6:E24) -> 1137236236 | F25: =SUBTOTAL(9,F6:F24) -> 22843199 | G25: =SUBTOTAL(9,G6:G24) -> 12392867748 | H25: =SUBTOTAL(9,H6:H24) -> 16408824052 | I25: =SUBTOTAL(9,I6:I24) -> 2540297416 | J25: =SUBTOTAL(9,J6:J24) -> 1636659270 | K25: =SUBTOTAL(9,K6:K24) -> 55272330 | ... U25: =SUBTOTAL(9,U6:U24) -> 52494422577 | V25: =IF(U25=0,"",((T25-U25)/U25)) -> 0.029801539
A26: 01 | B26: 1-2Q(1-6) | C26: 台產 | D26: =SUM('115自留(季)'!D23:G23) -> 0 | E26: =SUM('115自留(季)'!H23:K23) -> 0 | F26: =+'115自留(季)'!L23 | G26: =SUM('115自留(季)'!M23:N23) -> 0 | H26: =SUM('115自留(季)'!O23:P23) -> 0 | I26: =SUM('115自留(季)'!Q23:R23) -> 0 | J26: =+'115自留(季)'!S23 | K26: ='115自留(季)'!AI23 | L26: =SUM('115自留(季)'!T23:U23) -> 0 | M26: =+'115自留(季)'!V23 | N26: =SUM('115自留(季)'!X23:Y23) -> 0 | O26: =+'115自留(季)'!W23+'115自留(季)'!Z23+'115自留(季)'!AC23+'115自留(季)'!AD23 -> 0 | P26: =+'115自留(季)'!AA23 | Q26: =+'115自留(季)'!AB23+'115自留(季)'!AE23+'115自留(季)'!AF23 -> 0 | R26: =+'115自留(季)'!AG23+'115自留(季)'!AH23 -> 0 | S26: =+'115自留(季)'!AJ23 | T26: =SUM(D26:S26) -> 0 | U26: 3427472506 | V26: =IF(U26=0,"",((T26/U26)-1)) -> -1
A27: 02 | B27: 1-2Q(1-6) | C27: 兆豐 | D27: =SUM('115自留(季)'!D24:G24) -> 0 | E27: =SUM('115自留(季)'!H24:K24) -> 0 | F27: =+'115自留(季)'!L24 | G27: =SUM('115自留(季)'!M24:N24) -> 0 | H27: =SUM('115自留(季)'!O24:P24) -> 0 | I27: =SUM('115自留(季)'!Q24:R24) -> 0 | J27: =+'115自留(季)'!S24 | K27: ='115自留(季)'!AI24 | L27: =SUM('115自留(季)'!T24:U24) -> 0 | M27: =+'115自留(季)'!V24 | N27: =SUM('115自留(季)'!X24:Y24) -> 0 | O27: =+'115自留(季)'!W24+'115自留(季)'!Z24+'115自留(季)'!AC24+'115自留(季)'!AD24 -> 0 | P27: =+'115自留(季)'!AA24 | Q27: =+'115自留(季)'!AB24+'115自留(季)'!AE24+'115自留(季)'!AF24 -> 0 | R27: =+'115自留(季)'!AG24+'115自留(季)'!AH24 -> 0 | S27: =+'115自留(季)'!AJ24 | T27: =SUM(D27:S27) -> 0 | U27: 3247229446 | V27: =IF(U27=0,"",((T27/U27)-1)) -> -1
A28: 05 | B28: 1-2Q(1-6) | C28: 富邦 | D28: =SUM('115自留(季)'!D25:G25) -> 0 | E28: =SUM('115自留(季)'!H25:K25) -> 0 | F28: =+'115自留(季)'!L25 | G28: =SUM('115自留(季)'!M25:N25) -> 0 | H28: =SUM('115自留(季)'!O25:P25) -> 0 | I28: =SUM('115自留(季)'!Q25:R25) -> 0 | J28: =+'115自留(季)'!S25 | K28: ='115自留(季)'!AI25 | L28: =SUM('115自留(季)'!T25:U25) -> 0 | M28: =+'115自留(季)'!V25 | N28: =SUM('115自留(季)'!X25:Y25) -> 0 | O28: =+'115自留(季)'!W25+'115自留(季)'!Z25+'115自留(季)'!AC25+'115自留(季)'!AD25 -> 0 | P28: =+'115自留(季)'!AA25 | Q28: =+'115自留(季)'!AB25+'115自留(季)'!AE25+'115自留(季)'!AF25 -> 0 | R28: =+'115自留(季)'!AG25+'115自留(季)'!AH25 -> 0 | S28: =+'115自留(季)'!AJ25 | T28: =SUM(D28:S28) -> 0 | U28: 2.4189407e+10 | V28: =IF(U28=0,"",((T28/U28)-1)) -> -1
A29: 06 | B29: 1-2Q(1-6) | C29: 和泰 | D29: =SUM('115自留(季)'!D26:G26) -> 0 | E29: =SUM('115自留(季)'!H26:K26) -> 0 | F29: =+'115自留(季)'!L26 | G29: =SUM('115自留(季)'!M26:N26) -> 0 | H29: =SUM('115自留(季)'!O26:P26) -> 0 | I29: =SUM('115自留(季)'!Q26:R26) -> 0 | J29: =+'115自留(季)'!S26 | K29: ='115自留(季)'!AI26 | L29: =SUM('115自留(季)'!T26:U26) -> 0 | M29: =+'115自留(季)'!V26 | N29: =SUM('115自留(季)'!X26:Y26) -> 0 | O29: =+'115自留(季)'!W26+'115自留(季)'!Z26+'115自留(季)'!AC26+'115自留(季)'!AD26 -> 0 | P29: =+'115自留(季)'!AA26 | Q29: =+'115自留(季)'!AB26+'115自留(季)'!AE26+'115自留(季)'!AF26 -> 0 | R29: =+'115自留(季)'!AG26+'115自留(季)'!AH26 -> 0 | S29: =+'115自留(季)'!AJ26 | T29: =SUM(D29:S29) -> 0 | U29: 5723779472 | V29: =IF(U29=0,"",((T29/U29)-1)) -> -1
A30: 07 | B30: 1-2Q(1-6) | C30: 泰安 | D30: =SUM('115自留(季)'!D27:G27) -> 0 | E30: =SUM('115自留(季)'!H27:K27) -> 0 | F30: =+'115自留(季)'!L27 | G30: =SUM('115自留(季)'!M27:N27) -> 0 | H30: =SUM('115自留(季)'!O27:P27) -> 0 | I30: =SUM('115自留(季)'!Q27:R27) -> 0 | J30: =+'115自留(季)'!S27 | K30: ='115自留(季)'!AI27 | L30: =SUM('115自留(季)'!T27:U27) -> 0 | M30: =+'115自留(季)'!V27 | N30: =SUM('115自留(季)'!X27:Y27) -> 0 | O30: =+'115自留(季)'!W27+'115自留(季)'!Z27+'115自留(季)'!AC27+'115自留(季)'!AD27 -> 0 | P30: =+'115自留(季)'!AA27 | Q30: =+'115自留(季)'!AB27+'115自留(季)'!AE27+'115自留(季)'!AF27 -> 0 | R30: =+'115自留(季)'!AG27+'115自留(季)'!AH27 -> 0 | S30: =+'115自留(季)'!AJ27 | T30: =SUM(D30:S30) -> 0 | U30: 4825255742 | V30: =IF(U30=0,"",((T30/U30)-1)) -> -1
A31: 08 | B31: 1-2Q(1-6) | C31: 明台 | D31: =SUM('115自留(季)'!D28:G28) -> 0 | E31: =SUM('115自留(季)'!H28:K28) -> 0 | F31: =+'115自留(季)'!L28 | G31: =SUM('115自留(季)'!M28:N28) -> 0 | H31: =SUM('115自留(季)'!O28:P28) -> 0 | I31: =SUM('115自留(季)'!Q28:R28) -> 0 | J31: =+'115自留(季)'!S28 | K31: ='115自留(季)'!AI28 | L31: =SUM('115自留(季)'!T28:U28) -> 0 | M31: =+'115自留(季)'!V28 | N31: =SUM('115自留(季)'!X28:Y28) -> 0 | O31: =+'115自留(季)'!W28+'115自留(季)'!Z28+'115自留(季)'!AC28+'115自留(季)'!AD28 -> 0 | P31: =+'115自留(季)'!AA28 | Q31: =+'115自留(季)'!AB28+'115自留(季)'!AE28+'115自留(季)'!AF28 -> 0 | R31: =+'115自留(季)'!AG28+'115自留(季)'!AH28 -> 0 | S31: =+'115自留(季)'!AJ28 | T31: =SUM(D31:S31) -> 0 | U31: 6104265248 | V31: =IF(U31=0,"",((T31/U31)-1)) -> -1
A32: 09 | B32: 1-2Q(1-6) | C32: 南山 | D32: =SUM('115自留(季)'!D29:G29) -> 0 | E32: =SUM('115自留(季)'!H29:K29) -> 0 | F32: =+'115自留(季)'!L29 | G32: =SUM('115自留(季)'!M29:N29) -> 0 | H32: =SUM('115自留(季)'!O29:P29) -> 0 | I32: =SUM('115自留(季)'!Q29:R29) -> 0 | J32: =+'115自留(季)'!S29 | K32: ='115自留(季)'!AI29 | L32: =SUM('115自留(季)'!T29:U29) -> 0 | M32: =+'115自留(季)'!V29 | N32: =SUM('115自留(季)'!X29:Y29) -> 0 | O32: =+'115自留(季)'!W29+'115自留(季)'!Z29+'115自留(季)'!AC29+'115自留(季)'!AD29 -> 0 | P32: =+'115自留(季)'!AA29 | Q32: =+'115自留(季)'!AB29+'115自留(季)'!AE29+'115自留(季)'!AF29 -> 0 | R32: =+'115自留(季)'!AG29+'115自留(季)'!AH29 -> 0 | S32: =+'115自留(季)'!AJ29 | T32: =SUM(D32:S32) -> 0 | U32: 4410450487 | V32: =IF(U32=0,"",((T32/U32)-1)) -> -1
A33: 10 | B33: 1-2Q(1-6) | C33: 第一 | D33: =SUM('115自留(季)'!D30:G30) -> 0 | E33: =SUM('115自留(季)'!H30:K30) -> 0 | F33: =+'115自留(季)'!L30 | G33: =SUM('115自留(季)'!M30:N30) -> 0 | H33: =SUM('115自留(季)'!O30:P30) -> 0 | I33: =SUM('115自留(季)'!Q30:R30) -> 0 | J33: =+'115自留(季)'!S30 | K33: ='115自留(季)'!AI30 | L33: =SUM('115自留(季)'!T30:U30) -> 0 | M33: =+'115自留(季)'!V30 | N33: =SUM('115自留(季)'!X30:Y30) -> 0 | O33: =+'115自留(季)'!W30+'115自留(季)'!Z30+'115自留(季)'!AC30+'115自留(季)'!AD30 -> 0 | P33: =+'115自留(季)'!AA30 | Q33: =+'115自留(季)'!AB30+'115自留(季)'!AE30+'115自留(季)'!AF30 -> 0 | R33: =+'115自留(季)'!AG30+'115自留(季)'!AH30 -> 0 | S33: =+'115自留(季)'!AJ30 | T33: =SUM(D33:S33) -> 0 | U33: 3659598509 | V33: =IF(U33=0,"",((T33/U33)-1)) -> -1
A34: 12 | B34: 1-2Q(1-6) | C34: 旺旺友聯 | D34: =SUM('115自留(季)'!D31:G31) -> 0 | E34: =SUM('115自留(季)'!H31:K31) -> 0 | F34: =+'115自留(季)'!L31 | G34: =SUM('115自留(季)'!M31:N31) -> 0 | H34: =SUM('115自留(季)'!O31:P31) -> 0 | I34: =SUM('115自留(季)'!Q31:R31) -> 0 | J34: =+'115自留(季)'!S31 | K34: ='115自留(季)'!AI31 | L34: =SUM('115自留(季)'!T31:U31) -> 0 | M34: =+'115自留(季)'!V31 | N34: =SUM('115自留(季)'!X31:Y31) -> 0 | O34: =+'115自留(季)'!W31+'115自留(季)'!Z31+'115自留(季)'!AC31+'115自留(季)'!AD31 -> 0 | P34: =+'115自留(季)'!AA31 | Q34: =+'115自留(季)'!AB31+'115自留(季)'!AE31+'115自留(季)'!AF31 -> 0 | R34: =+'115自留(季)'!AG31+'115自留(季)'!AH31 -> 0 | S34: =+'115自留(季)'!AJ31 | T34: =SUM(D34:S34) -> 0 | U34: 5477686378 | V34: =IF(U34=0,"",((T34/U34)-1)) -> -1
A35: 13 | B35: 1-2Q(1-6) | C35: 新光 | D35: =SUM('115自留(季)'!D32:G32) -> 0 | E35: =SUM('115自留(季)'!H32:K32) -> 0 | F35: =+'115自留(季)'!L32 | G35: =SUM('115自留(季)'!M32:N32) -> 0 | H35: =SUM('115自留(季)'!O32:P32) -> 0 | I35: =SUM('115自留(季)'!Q32:R32) -> 0 | J35: =+'115自留(季)'!S32 | K35: ='115自留(季)'!AI32 | L35: =SUM('115自留(季)'!T32:U32) -> 0 | M35: =+'115自留(季)'!V32 | N35: =SUM('115自留(季)'!X32:Y32) -> 0 | O35: =+'115自留(季)'!W32+'115自留(季)'!Z32+'115自留(季)'!AC32+'115自留(季)'!AD32 -> 0 | P35: =+'115自留(季)'!AA32 | Q35: =+'115自留(季)'!AB32+'115自留(季)'!AE32+'115自留(季)'!AF32 -> 0 | R35: =+'115自留(季)'!AG32+'115自留(季)'!AH32 -> 0 | S35: =+'115自留(季)'!AJ32 | T35: =SUM(D35:S35) -> 0 | U35: 10446834849 | V35: =IF(U35=0,"",((T35/U35)-1)) -> -1
A36: 14 | B36: 1-2Q(1-6) | C36: 華南 | D36: =SUM('115自留(季)'!D33:G33) -> 0 | E36: =SUM('115自留(季)'!H33:K33) -> 0 | F36: =+'115自留(季)'!L33 | G36: =SUM('115自留(季)'!M33:N33) -> 0 | H36: =SUM('115自留(季)'!O33:P33) -> 0 | I36: =SUM('115自留(季)'!Q33:R33) -> 0 | J36: =+'115自留(季)'!S33 | K36: ='115自留(季)'!AI33 | L36: =SUM('115自留(季)'!T33:U33) -> 0 | M36: =+'115自留(季)'!V33 | N36: =SUM('115自留(季)'!X33:Y33) -> 0 | O36: =+'115自留(季)'!W33+'115自留(季)'!Z33+'115自留(季)'!AC33+'115自留(季)'!AD33 -> 0 | P36: =+'115自留(季)'!AA33 | Q36: =+'115自留(季)'!AB33+'115自留(季)'!AE33+'115自留(季)'!AF33 -> 0 | R36: =+'115自留(季)'!AG33+'115自留(季)'!AH33 -> 0 | S36: =+'115自留(季)'!AJ33 | T36: =SUM(D36:S36) -> 0 | U36: 5642085034 | V36: =IF(U36=0,"",((T36/U36)-1)) -> -1
A37: 15 | B37: 1-2Q(1-6) | C37: 國泰世紀 | D37: =SUM('115自留(季)'!D34:G34) -> 0 | E37: =SUM('115自留(季)'!H34:K34) -> 0 | F37: =+'115自留(季)'!L34 | G37: =SUM('115自留(季)'!M34:N34) -> 0 | H37: =SUM('115自留(季)'!O34:P34) -> 0 | I37: =SUM('115自留(季)'!Q34:R34) -> 0 | J37: =+'115自留(季)'!S34 | K37: ='115自留(季)'!AI34 | L37: =SUM('115自留(季)'!T34:U34) -> 0 | M37: =+'115自留(季)'!V34 | N37: =SUM('115自留(季)'!X34:Y34) -> 0 | O37: =+'115自留(季)'!W34+'115自留(季)'!Z34+'115自留(季)'!AC34+'115自留(季)'!AD34 -> 0 | P37: =+'115自留(季)'!AA34 | Q37: =+'115自留(季)'!AB34+'115自留(季)'!AE34+'115自留(季)'!AF34 -> 0 | R37: =+'115自留(季)'!AG34+'115自留(季)'!AH34 -> 0 | S37: =+'115自留(季)'!AJ34 | T37: =SUM(D37:S37) -> 0 | U37: 13774228782 | V37: =IF(U37=0,"",((T37/U37)-1)) -> -1
A38: 17 | B38: 1-2Q(1-6) | C38: 新安東京海上 | D38: =SUM('115自留(季)'!D35:G35) -> 0 | E38: =SUM('115自留(季)'!H35:K35) -> 0 | F38: =+'115自留(季)'!L35 | G38: =SUM('115自留(季)'!M35:N35) -> 0 | H38: =SUM('115自留(季)'!O35:P35) -> 0 | I38: =SUM('115自留(季)'!Q35:R35) -> 0 | J38: =+'115自留(季)'!S35 | K38: ='115自留(季)'!AI35 | L38: =SUM('115自留(季)'!T35:U35) -> 0 | M38: =+'115自留(季)'!V35 | N38: =SUM('115自留(季)'!X35:Y35) -> 0 | O38: =+'115自留(季)'!W35+'115自留(季)'!Z35+'115自留(季)'!AC35+'115自留(季)'!AD35 -> 0 | P38: =+'115自留(季)'!AA35 | Q38: =+'115自留(季)'!AB35+'115自留(季)'!AE35+'115自留(季)'!AF35 -> 0 | R38: =+'115自留(季)'!AG35+'115自留(季)'!AH35 -> 0 | S38: =+'115自留(季)'!AJ35 | T38: =SUM(D38:S38) -> 0 | U38: 9014093036 | V38: =IF(U38=0,"",((T38/U38)-1)) -> -1
A39: 18 | B39: 1-2Q(1-6) | C39: 中國信託 | D39: =SUM('115自留(季)'!D36:G36) -> 0 | E39: =SUM('115自留(季)'!H36:K36) -> 0 | F39: =+'115自留(季)'!L36 | G39: =SUM('115自留(季)'!M36:N36) -> 0 | H39: =SUM('115自留(季)'!O36:P36) -> 0 | I39: =SUM('115自留(季)'!Q36:R36) -> 0 | J39: =+'115自留(季)'!S36 | K39: ='115自留(季)'!AI36 | L39: =SUM('115自留(季)'!T36:U36) -> 0 | M39: =+'115自留(季)'!V36 | N39: =SUM('115自留(季)'!X36:Y36) -> 0 | O39: =+'115自留(季)'!W36+'115自留(季)'!Z36+'115自留(季)'!AC36+'115自留(季)'!AD36 -> 0 | P39: =+'115自留(季)'!AA36 | Q39: =+'115自留(季)'!AB36+'115自留(季)'!AE36+'115自留(季)'!AF36 -> 0 | R39: =+'115自留(季)'!AG36+'115自留(季)'!AH36 -> 0 | S39: =+'115自留(季)'!AJ36 | T39: =SUM(D39:S39) -> 0 | U39: 1205130474 | V39: =IF(U39=0,"",((T39/U39)-1)) -> -1
A40: 28 | B40: 1-2Q(1-6) | C40: 裕利安宜 | D40: =SUM('115自留(季)'!D37:G37) -> 0 | E40: =SUM('115自留(季)'!H37:K37) -> 0 | F40: =+'115自留(季)'!L37 | G40: =SUM('115自留(季)'!M37:N37) -> 0 | H40: =SUM('115自留(季)'!O37:P37) -> 0 | I40: =SUM('115自留(季)'!Q37:R37) -> 0 | J40: =+'115自留(季)'!S37 | K40: ='115自留(季)'!AI37 | L40: =SUM('115自留(季)'!T37:U37) -> 0 | M40: =+'115自留(季)'!V37 | N40: =SUM('115自留(季)'!X37:Y37) -> 0 | O40: =+'115自留(季)'!W37+'115自留(季)'!Z37+'115自留(季)'!AC37+'115自留(季)'!AD37 -> 0 | P40: =+'115自留(季)'!AA37 | Q40: =+'115自留(季)'!AB37+'115自留(季)'!AE37+'115自留(季)'!AF37 -> 0 | R40: =+'115自留(季)'!AG37+'115自留(季)'!AH37 -> 0 | S40: =+'115自留(季)'!AJ37 | T40: =SUM(D40:S40) -> 0 | U40: -3166214 | V40: =IF(U40=0,"",((T40/U40)-1)) -> -1
...

Sheet 歸屬
A1: 類 | B1: 歸屬 | C1: 代號 | E1: 險種
A2: 一 | B2: 火險 | C2: 0100 | E2: 一年期住宅火災保險
C3: 0200 | E3: 長期住宅火災保險
C4: 0300 | E4: 一年期商業火災保險
C5: 0400 | E5: 長期商業火災保險
A6: 二 | B6: 水險 | C6: 0500 | E6: 內陸運輸保險
C7: 0600 | E7: 貨物運輸保險
C8: 0700 | E8: 船體保險
C9: 0800 | E9: 漁船保險
A10: 三 | B10: 航空險 | C10: 0900 | E10: 航空保險
A11: 四 | B11: 汽車險 | C11: 1000 | D11: 車體損 | E11: 一般自用汽車財產損失險
C12: 1100 | E12: 一般商業汽車財產損失險
C13: 1200 | D13: 任意車責 | E13: 一般自用汽車責任險
C14: 1300 | E14: 一般商業汽車責任險
C15: 1400 | D15: 強制車 | E15: 強制自用汽車責任險
C16: 1500 | E16: 強制商業汽車責任險
C17: 1600 | D17: 強制機 | E17: 強制機車責任險
C18: 3200 | D18: 強制微型 | E18: 電動二輪車責任險
A19: 五 | B19: 意外險 | C19: 1700 | D19: 意責任 | E19: 一般責任保險
C20: 1800 | E20: 專業責任保險
C21: 1900 | D21: 意工 | E21: 工程保險
C22: 2100 | D22: 意信保 | E22: 保證保險
C23: 2200 | E23: 信用保險
C24: 2000 | D24: 意其他 | E24: 核能保險
C25: 2300 | E25: 其他財產保險
C26: 2600 | E26: 個人綜合保險
C27: 2700 | E27: 商業綜合保險
A28: 六 | B28: 傷害險 | C28: 2400 | E28: 傷害險
A29: 七 | B29: 天災險 | C29: 2500 | E29: 商業性地震險
C30: 2800 | E30: 颱風、洪水保險
C31: 2900 | E31: 政策性地震險
A32: 八 | B32: 健康險 | C32: 3000 | E32: 一年期健康險
C33: 3100 | E33: 長年期健康險
A34: 九 | B34: 國外分進 | C34: 9900 | E34: 國外分進業務
